Workbook

Sheet Precios
A1: Fecha | B1: S29E7 | C1: TMF27 | D1: TML27 | E1: T15E7 | F1: T31Y7
A2: 46072 | C2: 103 | E2: 121.45 | F2: 103.7
A3: 46073 | C3: 104.9 | E3: 121.8 | F3: 104.15
A4: 46076 | C4: 104 | E4: 121.9 | F4: 103.5
A5: 46077 | C5: 103.5 | E5: 123.55 | F5: 105.15
A6: 46078 | C6: 104.9 | E6: 123.6 | F6: 105.5
A7: 46079 | C7: 103.5 | E7: 124.15 | F7: 106
A8: 46080 | C8: 104.9 | E8: 124.5 | F8: 106
A9: 46083 | C9: 107 | E9: 124.8 | F9: 106.75
A10: 46084 | C10: 106.8 | E10: 124.3 | F10: 106.7
A11: 46085 | C11: 106.8 | E11: 124.6 | F11: 106.75
A12: 46086 | C12: 105.2 | E12: 124.6 | F12: 106.5
A13: 46087 | C13: 105 | E13: 124.65 | F13: 106
... A88: 46202 | C88: 116.2 | E88: 142.25 | F88: 122.85
A89: 46203 | C89: 116.5 | D89: 101.7 | E89: 142.84 | F89: 123.06
A90: 46204 | C90: 116.15 | D90: 101.6 | E90: 143 | F90: 123.7
A91: 46205 | C91: 116.2 | D91: 101.7 | E91: 143.249 | F91: 123.45
A92: 46206 | C92: 116.55 | D92: 102.3 | E92: 144 | F92: 123.61
A93: 46209 | C93: 116.6 | D93: 102.5 | E93: 143.2 | F93: 123.999
A94: 46210 | C94: 116.65 | D94: 102.8 | E94: 144.2 | F94: 124.5
A95: 46211 | C95: 117.05 | D95: 102.9 | E95: 144 | F95: 124.701
A96: 46213 | C96: 118.95 | D96: 104 | E96: 144.4 | F96: 126
A97: 46216 | C97: 117 | D97: 102.9 | E97: 144.32 | F97: 124.5
A98: 46217 | C98: 117.1 | D98: 103 | E98: 144.05 | F98: 124.439
A99: 46218 | C99: 117.1 | D99: 103.75 | E99: 144.35 | F99: 124.45
A100: 46219 | C100: 116.95 | D100: 103.3 | E100: 143.8 | F100: 124.32
... A131: 46265 | C131: 121.15 | D131: 106.85 | E131: 146.94 | F131: 124.85
A132: 46266 | B132: 1.0090604 | C132: 1.2130008 | D132: 1.0690003 | E132: 1.471868 | F132: 1.2513123
A133: 46267 | B133: 1.0100604 | C133: 1.2147051 | D133: 1.0690074 | E133: 1.4720118 | F133: 1.2529571
A134: 46268 | B134: 1.010843 | C134: 1.2157257 | D134: 1.0687348 | E134: 1.4736208 | F134: 1.2542112
A135: 46269 | B135: 1.0127881 | C135: 1.2178138 | D135: 1.0742336 | E135: 1.4765108 | F135: 1.2585695
A136: 46272 | B136: 1.0133567 | C136: 1.2177764 | D136: 1.0713624 | E136: 1.4698733 | F136: 1.2595069
A137: 46273 | B137: 1.0132366 | C137: 1.217781 | D137: 1.0716682 | E137: 1.4748975 | F137: 1.2577613
A138: 46274 | B138: 1.0115058 | C138: 1.2187584 | D138: 1.074995 | E138: 1.4749057 | F138: 1.2568113
A139: 46275 | B139: 1.0156022 | C139: 1.217141 | D139: 1.0745 | E139: 1.4784657 | F139: 1.2607528
A140: 46276 | B140: 1.017182 | C140: 1.2200571 | D140: 1.0730104 | E140: 1.4830342 | F140: 1.2616848
A141: 46279 | B141: 1.0194177 | C141: 1.2240582 | D141: 1.0804226 | E141: 1.4858866 | F141: 1.2666343
A142: 46280 | B142: 1.0204413 | C142: 1.225872 | D142: 1.0821337 | E142: 1.4879084 | F142: 1.265318
A143: 46281 | B143: 1.0214054 | C143: 1.2271993 | D143: 1.0849929 | E143: 1.4886435 | F143: 1.2667625
... A150: 46290 | B150: 1.0266373 | C150: 1.2375667 | D150: 1.0920285 | E150: 1.4954675 | F150: 1.2697028
...

Sheet Tamar
A1: Fecha | B1: Tamar
A2: 45659 | B2: 34.3125
A3: 45660 | B3: 34.5
A4: 45663 | B4: 34.75
A5: 45664 | B5: 34.8125
A6: 45665 | B6: 33.9375
A7: 45666 | B7: 34.1875
A8: 45667 | B8: 34.1875
A9: 45670 | B9: 34.25
A10: 45671 | B10: 34.5625
A11: 45672 | B11: 32.875
A12: 45673 | B12: 33.1875
A13: 45674 | B13: 32.5625
... A255: 46042 | B255: 36.6875
A256: 46043 | B256: 36.9375 | C256: ,
A257: 46044 | B257: 38.0625
A258: 46045 | B258: 37.8125
A259: 46048 | B259: 35.625
A260: 46049 | B260: 34.5
A261: 46050 | B261: 32.625
A262: 46051 | B262: 31.75
A263: 46052 | B263: 32.9375 | C263: ,
A264: 46055 | B264: 32.6875
A265: 46056 | B265: 34
A266: 46057 | B266: 32.5625
A267: 46058 | B267: 32.1875
A268: 46059 | B268: 31.8125
A269: 46062 | B269: 31.1875
A270: 46063 | B270: 31.375
A271: 46064 | B271: 31.5625
A272: 46065 | B272: 32.375
A273: 46066 | B273: 33.4375
A274: 46071 | B274: 33.6875
A275: 46072 | B275: 34.625
... A419: 46288 | B419: 23.6875
A420: =+WORKDAY(A419,1,Feriados!$A$2:$A$38) -> 46289 | B420: =+IFERROR(VLOOKUP(A420,[2]Variables!$M:$N,2,0),0) -> 23.75
A421: =+WORKDAY(A420,1,Feriados!$A$2:$A$38) -> 46290 | B421: =+IFERROR(VLOOKUP(A421,[2]Variables!$M:$N,2,0),0) -> 23.625
A422: =+WORKDAY(A421,1,Feriados!$A$2:$A$38) -> 46293 | B422: =+IFERROR(VLOOKUP(A422,[2]Variables!$M:$N,2,0),0) -> 23.4375
A423: =+WORKDAY(A422,1,Feriados!$A$2:$A$38) -> 46294 | B423: =+IFERROR(VLOOKUP(A423,[2]Variables!$M:$N,2,0),0) -> 24.3125
A424: =+WORKDAY(A423,1,Feriados!$A$2:$A$38) -> 46295 | B424: =+IFERROR(VLOOKUP(A424,[2]Variables!$M:$N,2,0),0) -> 24.125
...

Sheet Feriados
A1: Feriados
A2: =+[3]Hoja1!$B31 -> 46167
A3: =+[3]Hoja1!$B32 -> 46188
A4: =+[3]Hoja1!$B33 -> 46212
A5: =+[3]Hoja1!$B34 -> 46213
A6: =+[3]Hoja1!$B35 -> 46251
A7: =+[3]Hoja1!$B36 -> 46307
A8: =+[3]Hoja1!$B37 -> 46332
A9: =+[3]Hoja1!$B38 -> 46335
A10: =+[3]Hoja1!$B39 -> 46336
A11: =+[3]Hoja1!$B40 -> 46349
A12: =+[3]Hoja1!$B41 -> 46363
A13: =+[3]Hoja1!$B42 -> 46364
A14: =+[3]Hoja1!$B43 -> 46381

Sheet Lecaps
A1: Ticker | B1: Emisión | C1: Vencimiento | D1: Tasa
A2: T15E7 | B2: 45688 | C2: 46402 | D2: 0.0205
A3: S29E7 | B3: 46265 | C3: 46416 | D3: 0.0219
A4: T31Y7 | B4: 46006 | C4: 46538 | D4: 0.024

Sheet Letam
A1: Ticker | B1: Emisión | C1: Vencimiento | D1: Tasa
A2: TMF27 | B2: 46066 | C2: 46444 | D2: 0.065
A3: TML27 | B3: 46203 | C3: 46598 | D3: 0.054
